Workbook

Sheet 01_ParSheet
A1: 243 Ways Social Par Sheet
A2: 优先级：U1
A4: 版本定位
A5: 项目 | B5: v1 | C5: v2
A6: 定位 | B6: 纯 Base 低波动 | C6: SC1 Respin + SC2 Free Spin
A7: 自然 RTP 口径 | B7: 95.33% | C7: 设计约 93.00%；1M 92.94%
A8: Max Win | B8: 1000x | C8: 5000x
A11: 普通符号赔率
A12: 符号 | B12: v1 3连 | C12: v1 4连 | D12: v1 5连 | E12: v2 3连 | F12: v2 4连 | G12: v2 5连
A13: K | B13: 0.5 | C13: 1 | D13: 10 | E13: 0.6 | F13: 1 | G13: 10
A14: Q | B14: 0.4 | C14: 0.8 | D14: 10 | E14: 0.4 | F14: 0.8 | G14: 10
A15: J | B15: 0.4 | C15: 0.8 | D15: 5 | E15: 0.4 | F15: 0.8 | G15: 10
A16: 10 | B16: 0.3 | C16: 0.5 | D16: 5 | E16: 0.3 | F16: 0.8 | G16: 5
A17: 9 | B17: 0.3 | C17: 0.5 | D17: 5 | E17: 0.3 | F17: 0.8 | G17: 5
A18: 8 | B18: 0.3 | C18: 0.5 | D18: 5 | E18: 0.3 | F18: 0.8 | G18: 5
A19: 7 | B19: 0.3 | C19: 0.5 | D19: 5 | E19: 0.3 | F19: 0.8 | G19: 5
A22: Feature 配置
A23: 机制 | B23: 触发 | C23: 规则 | E23: 备注
A24: SC1 Respin | B24: 3+ SC1 | C24: 初始 3 次；SC1 粘住；新 SC1 续 1 次；最多 5 次 | E24: SC2 在 Respin 内不触发
A25: SC2 Free Spin | B25: 3+ SC2 | C25: 6 次 Free Spin；每次普通 ways ×2；不 retrigger | E25: SC1/SC2 在 FS 内不再触发
A26: 同时触发 | B26: 两个条件同时满足 | C26: Free Spin 优先 | E26: Respin 不补发、不延后
A27: 嵌套 | B27: 任何 Feature 内 | C27: Free Spin 与 Respin 不互相嵌套 | E27: 每个 Base Spin 最多一种 Feature
A28: Feature Buy | B28: 主动购买 | C28: 10.5x 总下注，购买 6 次 Free Spin | E28: 单独 RTP，不混入自然 RTP
A31: SC 可见概率
A32: Reel | B32: SC1 概率 | C32: SC2 概率 | D32: 说明
A33: Reel 1 | B33: 0.15 | C33: 0.15 | D33: 每条轴 3/20 窗口可命中
A34: Reel 2 | B34: 0.15 | C34: 0.15
A35: Reel 3 | B35: 0.15 | C35: 0.15
A36: Reel 4 | B36: 0.15 | C36: 0.15
A37: Reel 5 | B37: 0.15 | C37: 0 | D37: SC2 不在第 5 轴
A40: 技术底稿：期望 ways
A41: 符号 | B41: v1 E3 | C41: v1 E4 | D41: v1 E5 | E41: v2 E3 | F41: v2 E4 | G41: v2 E5
A42: K | B42: 0.05011875 | C42: 0.022553437 | D42: 0.018452812 | E42: 0.05011875 | F42: 0.022553437 | G42: 0.018452812
A43: Q | B43: 0.05011875 | C43: 0.022553437 | D43: 0.018452812 | E43: 0.05011875 | F43: 0.022553437 | G43: 0.018452812
A44: J | B44: 0.0189 | C44: 0.00567 | D44: 0.00243 | E44: 0.0189 | F44: 0.00567 | G44: 0.00243
A45: 10 | B45: 0.05011875 | C45: 0.022553437 | D45: 0.018452812 | E45: 0.05011875 | F45: 0.022553437 | G45: 0.018452812
A46: 9 | B46: 0.05011875 | C46: 0.022553437 | D46: 0.018452812 | E46: 0.05011875 | F46: 0.022553437 | G46: 0.018452812
A47: 8 | B47: 0.05011875 | C47: 0.022553437 | D47: 0.018452812 | E47: 0.0189 | F47: 0.004455 | G47: 0.003645
A48: 7 | B48: 0.05011875 | C48: 0.022553437 | D48: 0.018452812 | E48: 0.0189 | F48: 0.00567 | G48: 0.00243
A50: 说明 | B50: E[ways 3/4/5] 已由 5 条 20 停点滚轴预计算；本作品重点展示赔率到 RTP 的公式链，不展开滚轴输入。
...

Sheet 02_RTP计算
A1: RTP 计算
A2: Base、Scatter、Free Spin、Respin、Feature Buy 在同一页完成
A4: v1 Base ways RTP
A5: 符号 | B5: 3连 RTP | C5: 4连 RTP | D5: 5连 RTP | E5: 合计
A6: K | B6: ='01_ParSheet'!B13*'01_ParSheet'!B42 -> 0.025059375 | C6: ='01_ParSheet'!C13*'01_ParSheet'!C42 -> 0.022553437 | D6: ='01_ParSheet'!D13*'01_ParSheet'!D42 -> 0.18452812 | E6: =SUM(B6:D6) -> 0.23214094
A7: Q | B7: ='01_ParSheet'!B14*'01_ParSheet'!B43 -> 0.0200475 | C7: ='01_ParSheet'!C14*'01_ParSheet'!C43 -> 0.01804275 | D7: ='01_ParSheet'!D14*'01_ParSheet'!D43 -> 0.18452812 | E7: =SUM(B7:D7) -> 0.22261837
A8: J | B8: ='01_ParSheet'!B15*'01_ParSheet'!B44 -> 0.00756 | C8: ='01_ParSheet'!C15*'01_ParSheet'!C44 -> 0.004536 | D8: ='01_ParSheet'!D15*'01_ParSheet'!D44 -> 0.01215 | E8: =SUM(B8:D8) -> 0.024246
A9: 10 | B9: ='01_ParSheet'!B16*'01_ParSheet'!B45 -> 0.015035625 | C9: ='01_ParSheet'!C16*'01_ParSheet'!C45 -> 0.011276719 | D9: ='01_ParSheet'!D16*'01_ParSheet'!D45 -> 0.092264062 | E9: =SUM(B9:D9) -> 0.11857641
A10: 9 | B10: ='01_ParSheet'!B17*'01_ParSheet'!B46 -> 0.015035625 | C10: ='01_ParSheet'!C17*'01_ParSheet'!C46 -> 0.011276719 | D10: ='01_ParSheet'!D17*'01_ParSheet'!D46 -> 0.092264062 | E10: =SUM(B10:D10) -> 0.11857641
A11: 8 | B11: ='01_ParSheet'!B18*'01_ParSheet'!B47 -> 0.015035625 | C11: ='01_ParSheet'!C18*'01_ParSheet'!C47 -> 0.011276719 | D11: ='01_ParSheet'!D18*'01_ParSheet'!D47 -> 0.092264062 | E11: =SUM(B11:D11) -> 0.11857641
A12: 7 | B12: ='01_ParSheet'!B19*'01_ParSheet'!B48 -> 0.015035625 | C12: ='01_ParSheet'!C19*'01_ParSheet'!C48 -> 0.011276719 | D12: ='01_ParSheet'!D19*'01_ParSheet'!D48 -> 0.092264062 | E12: =SUM(B12:D12) -> 0.11857641
A13: v1 Base | B13: =SUM(B6:B12) -> 0.11280937 | C13: =SUM(C6:C12) -> 0.090239062 | D13: =SUM(D6:D12) -> 0.7502625 | E13: =SUM(E6:E12) -> 0.95331094
A16: v2 Base ways RTP
A17: 符号 | B17: 3连 RTP | C17: 4连 RTP | D17: 5连 RTP | E17: 合计
A18: K | B18: ='01_ParSheet'!E13*'01_ParSheet'!E42 -> 0.03007125 | C18: ='01_ParSheet'!F13*'01_ParSheet'!F42 -> 0.022553437 | D18: ='01_ParSheet'!G13*'01_ParSheet'!G42 -> 0.18452812 | E18: =SUM(B18:D18) -> 0.23715281
A19: Q | B19: ='01_ParSheet'!E14*'01_ParSheet'!E43 -> 0.0200475 | C19: ='01_ParSheet'!F14*'01_ParSheet'!F43 -> 0.01804275 | D19: ='01_ParSheet'!G14*'01_ParSheet'!G43 -> 0.18452812 | E19: =SUM(B19:D19) -> 0.22261837
A20: J | B20: ='01_ParSheet'!E15*'01_ParSheet'!E44 -> 0.00756 | C20: ='01_ParSheet'!F15*'01_ParSheet'!F44 -> 0.004536 | D20: ='01_ParSheet'!G15*'01_ParSheet'!G44 -> 0.0243 | E20: =SUM(B20:D20) -> 0.036396
A21: 10 | B21: ='01_ParSheet'!E16*'01_ParSheet'!E45 -> 0.015035625 | C21: ='01_ParSheet'!F16*'01_ParSheet'!F45 -> 0.01804275 | D21: ='01_ParSheet'!G16*'01_ParSheet'!G45 -> 0.092264062 | E21: =SUM(B21:D21) -> 0.12534244
A22: 9 | B22: ='01_ParSheet'!E17*'01_ParSheet'!E46 -> 0.015035625 | C22: ='01_ParSheet'!F17*'01_ParSheet'!F46 -> 0.01804275 | D22: ='01_ParSheet'!G17*'01_ParSheet'!G46 -> 0.092264062 | E22: =SUM(B22:D22) -> 0.12534244
A23: 8 | B23: ='01_ParSheet'!E18*'01_ParSheet'!E47 -> 0.00567 | C23: ='01_ParSheet'!F18*'01_ParSheet'!F47 -> 0.003564 | D23: ='01_ParSheet'!G18*'01_ParSheet'!G47 -> 0.018225 | E23: =SUM(B23:D23) -> 0.027459
A24: 7 | B24: ='01_ParSheet'!E19*'01_ParSheet'!E48 -> 0.00567 | C24: ='01_ParSheet'!F19*'01_ParSheet'!F48 -> 0.004536 | D24: ='01_ParSheet'!G19*'01_ParSheet'!G48 -> 0.01215 | E24: =SUM(B24:D24) -> 0.022356
A25: v2 Base | B25: =SUM(B18:B24) -> 0.09909 | C25: =SUM(C18:C24) -> 0.089317687 | D25: =SUM(D18:D24) -> 0.60825937 | E25: =SUM(E18:E24) -> 0.79666706
A28: Scatter 触发
A29: 符号 | B29: 有效轴数 | C29: 每轴概率 | D29: 恰好 3 | E29: 恰好 4 | F29: 恰好 5 | G29: 至少 3
A30: SC1 | B30: =COUNTIF('01_ParSheet'!B33:B37,">0") -> 5 | C30: =SUM('01_ParSheet'!B33:B37)/B30 -> 0.15 | D30: =COMBIN(B30,3)*C30^3*(1-C30)^(B30-3) -> 0.024384375 | E30: =COMBIN(B30,4)*C30^4*(1-C30)^(B30-4) -> 0.0021515625 | F30: =IF(B30<5,0,COMBIN(B30,5)*C30^5*(1-C30)^(B30-5)) -> 7.59375e-05 | G30: =SUM(D30:F30) -> 0.026611875
A31: SC2 | B31: =COUNTIF('01_ParSheet'!C33:C37,">0") -> 4 | C31: =SUM('01_ParSheet'!C33:C37)/B31 -> 0.15 | D31: =COMBIN(B31,3)*C31^3*(1-C31)^(B31-3) -> 0.011475 | E31: =COMBIN(B31,4)*C31^4*(1-C31)^(B31-4) -> 0.00050625 | F31: =IF(B31<5,0,COMBIN(B31,5)*C31^5*(1-C31)^(B31-5)) -> 0 | G31: =SUM(D31:F31) -> 0.01198125
A34: Feature RTP
A35: 来源 | B35: 1M 触发率 | C35: 平均赢奖 | D35: RTP 贡献 | E35: 说明
A36: Free Spin | B36: 0.011903 | C36: 9.5064 | D36: =B36*C36 -> 0.11315468 | E36: 6 次 ×2；FS 优先
A37: Respin | B37: 0.021703 | C37: 0.93 | D37: =B37*C37 -> 0.02018379 | E37: 优先扣除同时触发
A38: Feature 合计 | D38: =SUM(D36:D37) -> 0.13333847 | E38: 自然 RTP 的 Feature 部分
A41: RTP 汇总
A42: 版本 | B42: Base RTP | C42: Feature RTP | D42: 设计 RTP | E42: 口径
A43: v1 | B43: =E13 -> 0.95331094 | C43: =0 -> 0 | D43: =B43+C43 -> 0.95331094 | E43: 纯 Base
A44: v2 | B44: =E25 -> 0.79666706 | C44: =D38 -> 0.13333847 | D44: =B44+C44 -> 0.93000553 | E44: 设计约 93.00%；1M 见下一表
A47: Feature Buy RTP
A48: 项目 | B48: 值 | C48: 单位 | D48: 说明
A49: 购买价格 | B49: 10.5 | C49: × bet | D49: 6 次 Free Spin
A50: 平均 FS 赢奖 | B50: =C36 -> 9.5064 | C50: × bet | D50: 来自同一 1M 模拟
A51: 买入 RTP | B51: =B50/B49 -> 0.90537143 | C51: RTP | D51: 单独产品；不混入自然 RTP
...

Sheet 03_结果对比
A1: v1 与 v2 结果对比
A2: v2 的设计口径约 93.00%，同一 1M 模拟为 92.94%
A4: 核心指标
A5: 指标 | B5: v1 | C5: v2 | D5: 变化
A6: 设计 RTP | B6: ='02_RTP计算'!D43 -> 0.95331094 | C6: ='02_RTP计算'!D44 -> 0.93000553 | D6: =C6-B6 -> -0.023305406
A7: 1M RTP | B7: 0.954059 | C7: 0.929436 | D7: =C7-B7 -> -0.024623
A8: Base RTP | B8: ='02_RTP计算'!B43 -> 0.95331094 | C8: ='02_RTP计算'!B44 -> 0.79666706 | D8: =C8-B8 -> -0.15664387
A9: Feature RTP | B9: ='02_RTP计算'!C43 -> 0 | C9: ='02_RTP计算'!C44 -> 0.13333847 | D9: =C9-B9 -> 0.13333847
A10: Hit rate | B10: 0.415546 | C10: 0.36072 | D10: =C10-B10 -> -0.054826
A11: 单转 SD | B11: 2.5101 | C11: 2.8799 | D11: =C11-B11 -> 0.3698
A12: Max Win 封顶 | B12: 1000 | C12: 5000 | D12: =C12-B12 -> 4000
A13: 1M 观察最大赢 | B13: 25 | C13: 90
A14: SC1 原始触发 | C14: ='02_RTP计算'!G30 -> 0.026611875
A15: SC2 原始触发 | C15: ='02_RTP计算'!G31 -> 0.01198125
A16: Feature Buy RTP | C16: ='02_RTP计算'!B51 -> 0.90537143
A19: Patch Notes
A20: 改动 | B20: v1 | C20: v2 | D20: 设计意图
A21: 符号与 Base | B21: 7 个普通符号，纯 Base | C21: 保持 7 个普通符号，Base 降至 79.67% | D21: 把更多 RTP 转移给 Feature
A22: Feature | B22: 无 | C22: SC1 Respin；SC2 Free Spin | D22: 区分短 Respin 与长 Free Spin
A23: 触发优先 | B23: 无 | C23: 同时触发时 Free Spin 优先 | D23: 避免一次 Spin 重复领取两种 Feature
A24: 波动 | B24: SD 2.51；Max 1000x | C24: SD 2.88；Max 5000x | D24: 提高上限与尾部赢奖
A25: 商业化 | B25: 无 Buy | C25: 10.5x Feature Buy，RTP 90.54% | D25: 增加主动金币 sink
A28: 面试结论
A29: 结论 | B29: v1 用高 hit、低波动保持平滑体验；v2 用两种 Scatter 和独立 Feature 提高波动与上限。
A30: 机制边界 | B30: FS 与 Respin 不嵌套；同盘同时触发 Free Spin 优先，进入任一 Feature 后另一套 Scatter 不再触发。
A31: RTP | B31: v2 设计约 93.00%，1M 92.94%；差异约 0.06pp，单独报告而不是统一成一个数。
A32: 商业化 | B32: Feature Buy 是 Free Spin 的独立入口，10.5x 售价对应 90.54% RTP，不能直接加到自然 RTP。
